Workbook

Sheet ORIGINAL A
A1: PORTS OF LOADING | B1: PORTS OF DISCHARGE | M1: PORTS OF DISCHARGE | N1: Transport Additional surcharge (TAD) in USD on top of Gioia Tauro rates
N3: 20' | O3: 40' | P3: 40H
B4: Genoa, La Spezia | E4: Trieste | H4: Gioia Tauro | M4: LEGHORN | N4: 0 | O4: 0 | P4: 0
B5: 20' | C5: 40' | D5: 40H | E5: 20' | F5: 40' | G5: 40H | H5: 20' | I5: 40' | J5: 40H | M5: CIVITAVECCHIA | N5: 0 | O5: 0 | P5: 0
A6: HONG KONG | B6: =RANDBETWEEN(2000,5000) -> 4801 | C6: =RANDBETWEEN(2000,5000) -> 4286 | D6: =RANDBETWEEN(2000,5000) -> 4324 | E6: =RANDBETWEEN(2000,5000) -> 4338 | F6: =RANDBETWEEN(2000,5000) -> 2463 | G6: =RANDBETWEEN(2000,5000) -> 3849 | H6: =RANDBETWEEN(2000,5000) -> 2765 | I6: =RANDBETWEEN(2000,5000) -> 2730 | J6: =RANDBETWEEN(2000,5000) -> 4649 | M6: NAPLES | N6: 0 | O6: 0 | P6: 0
A7: SHEKOU | B7: =RANDBETWEEN(2000,5000) -> 3676 | C7: =RANDBETWEEN(2000,5000) -> 2718 | D7: =RANDBETWEEN(2000,5000) -> 2941 | E7: =RANDBETWEEN(2000,5000) -> 2762 | F7: =RANDBETWEEN(2000,5000) -> 2657 | G7: =RANDBETWEEN(2000,5000) -> 3584 | H7: =RANDBETWEEN(2000,5000) -> 4817 | I7: =RANDBETWEEN(2000,5000) -> 4210 | J7: =RANDBETWEEN(2000,5000) -> 3138 | M7: SALERNO | N7: =RANDBETWEEN(50,1000) -> 96 | O7: =RANDBETWEEN(50,1000) -> 792 | P7: =RANDBETWEEN(50,1000) -> 718
A8: YANTlAN | B8: =RANDBETWEEN(2000,5000) -> 4376 | C8: =RANDBETWEEN(2000,5000) -> 3888 | D8: =RANDBETWEEN(2000,5000) -> 2726 | E8: =RANDBETWEEN(2000,5000) -> 4059 | F8: =RANDBETWEEN(2000,5000) -> 3504 | G8: =RANDBETWEEN(2000,5000) -> 2534 | H8: =RANDBETWEEN(2000,5000) -> 3210 | I8: =RANDBETWEEN(2000,5000) -> 3525 | J8: =RANDBETWEEN(2000,5000) -> 3307 | M8: RAVENNA | N8: =RANDBETWEEN(50,1000) -> 161 | O8: =RANDBETWEEN(50,1000) -> 511 | P8: =RANDBETWEEN(50,1000) -> 282
A9: NANSHA | B9: =RANDBETWEEN(2000,5000) -> 4918 | C9: =RANDBETWEEN(2000,5000) -> 2794 | D9: =RANDBETWEEN(2000,5000) -> 3477 | E9: =RANDBETWEEN(2000,5000) -> 3304 | F9: =RANDBETWEEN(2000,5000) -> 3707 | G9: =RANDBETWEEN(2000,5000) -> 3230 | H9: =RANDBETWEEN(2000,5000) -> 3080 | I9: =RANDBETWEEN(2000,5000) -> 4185 | J9: =RANDBETWEEN(2000,5000) -> 4627 | M9: VENICE | N9: =RANDBETWEEN(50,1000) -> 100 | O9: =RANDBETWEEN(50,1000) -> 573 | P9: =RANDBETWEEN(50,1000) -> 531
A10: XIAMEN | B10: =RANDBETWEEN(2000,5000) -> 3889 | C10: =RANDBETWEEN(2000,5000) -> 3140 | D10: =RANDBETWEEN(2000,5000) -> 2867 | E10: =RANDBETWEEN(2000,5000) -> 3262 | F10: =RANDBETWEEN(2000,5000) -> 3116 | G10: =RANDBETWEEN(2000,5000) -> 2111 | H10: =RANDBETWEEN(2000,5000) -> 3149 | I10: =RANDBETWEEN(2000,5000) -> 4172 | J10: =RANDBETWEEN(2000,5000) -> 2250 | M10: ANCONA | N10: =RANDBETWEEN(50,1000) -> 728 | O10: =RANDBETWEEN(50,1000) -> 258 | P10: =RANDBETWEEN(50,1000) -> 399
A11: FlJZHOlJ | B11: =RANDBETWEEN(2000,5000) -> 3521 | C11: =RANDBETWEEN(2000,5000) -> 4997 | D11: =RANDBETWEEN(2000,5000) -> 3718 | E11: =RANDBETWEEN(2000,5000) -> 2453 | F11: =RANDBETWEEN(2000,5000) -> 3196 | G11: =RANDBETWEEN(2000,5000) -> 2106 | H11: =RANDBETWEEN(2000,5000) -> 2745 | I11: =RANDBETWEEN(2000,5000) -> 3634 | J11: =RANDBETWEEN(2000,5000) -> 3425 | M11: BARI | N11: =RANDBETWEEN(50,1000) -> 469 | O11: =RANDBETWEEN(50,1000) -> 793 | P11: =RANDBETWEEN(50,1000) -> 506
A12: SHANTOU | B12: =RANDBETWEEN(2000,5000) -> 3983 | C12: =RANDBETWEEN(2000,5000) -> 3943 | D12: =RANDBETWEEN(2000,5000) -> 2574 | E12: =RANDBETWEEN(2000,5000) -> 4213 | F12: =RANDBETWEEN(2000,5000) -> 2557 | G12: =RANDBETWEEN(2000,5000) -> 4528 | H12: =RANDBETWEEN(2000,5000) -> 3457 | I12: =RANDBETWEEN(2000,5000) -> 2464 | J12: =RANDBETWEEN(2000,5000) -> 3584 | M12: AUGUSTA | N12: =RANDBETWEEN(50,1000) -> 926 | O12: =RANDBETWEEN(50,1000) -> 697 | P12: =RANDBETWEEN(50,1000) -> 762
A13: QINZHOU | B13: =RANDBETWEEN(2000,5000) -> 4734 | C13: =RANDBETWEEN(2000,5000) -> 2043 | D13: =RANDBETWEEN(2000,5000) -> 2766 | E13: =RANDBETWEEN(2000,5000) -> 2240 | F13: =RANDBETWEEN(2000,5000) -> 3712 | G13: =RANDBETWEEN(2000,5000) -> 4927 | H13: =RANDBETWEEN(2000,5000) -> 2159 | I13: =RANDBETWEEN(2000,5000) -> 2083 | J13: =RANDBETWEEN(2000,5000) -> 4673 | M13: POZZALLO | N13: =RANDBETWEEN(50,1000) -> 93 | O13: =RANDBETWEEN(50,1000) -> 945 | P13: =RANDBETWEEN(50,1000) -> 826
A14: SHANGHAl | B14: =RANDBETWEEN(2000,5000) -> 4313 | C14: =RANDBETWEEN(2000,5000) -> 3914 | D14: =RANDBETWEEN(2000,5000) -> 3002 | E14: =RANDBETWEEN(2000,5000) -> 4165 | F14: =RANDBETWEEN(2000,5000) -> 3535 | G14: =RANDBETWEEN(2000,5000) -> 2298 | H14: =RANDBETWEEN(2000,5000) -> 4921 | I14: =RANDBETWEEN(2000,5000) -> 3161 | J14: =RANDBETWEEN(2000,5000) -> 4036 | M14: PALERMO | N14: =RANDBETWEEN(50,1000) -> 724 | O14: =RANDBETWEEN(50,1000) -> 508 | P14: =RANDBETWEEN(50,1000) -> 803
A15: NlNGBO | B15: =RANDBETWEEN(2000,5000) -> 4589 | C15: =RANDBETWEEN(2000,5000) -> 4072 | D15: =RANDBETWEEN(2000,5000) -> 2994 | E15: =RANDBETWEEN(2000,5000) -> 2674 | F15: =RANDBETWEEN(2000,5000) -> 3004 | G15: =RANDBETWEEN(2000,5000) -> 2828 | H15: =RANDBETWEEN(2000,5000) -> 3044 | I15: =RANDBETWEEN(2000,5000) -> 3140 | J15: =RANDBETWEEN(2000,5000) -> 4174 | M15: CAGLIARI | N15: =RANDBETWEEN(50,1000) -> 335 | O15: =RANDBETWEEN(50,1000) -> 689 | P15: =RANDBETWEEN(50,1000) -> 510
A16: QINGDAO | B16: =RANDBETWEEN(2000,5000) -> 4128 | C16: =RANDBETWEEN(2000,5000) -> 4572 | D16: =RANDBETWEEN(2000,5000) -> 4171 | E16: =RANDBETWEEN(2000,5000) -> 2890 | F16: =RANDBETWEEN(2000,5000) -> 2660 | G16: =RANDBETWEEN(2000,5000) -> 2315 | H16: =RANDBETWEEN(2000,5000) -> 4115 | I16: =RANDBETWEEN(2000,5000) -> 4774 | J16: =RANDBETWEEN(2000,5000) -> 2108
A17: XINGANG | B17: =RANDBETWEEN(2000,5000) -> 3224 | C17: =RANDBETWEEN(2000,5000) -> 4021 | D17: =RANDBETWEEN(2000,5000) -> 2309 | E17: =RANDBETWEEN(2000,5000) -> 2831 | F17: =RANDBETWEEN(2000,5000) -> 4248 | G17: =RANDBETWEEN(2000,5000) -> 4668 | H17: =RANDBETWEEN(2000,5000) -> 2579 | I17: =RANDBETWEEN(2000,5000) -> 2357 | J17: =RANDBETWEEN(2000,5000) -> 3783
A18: DALlAN | B18: =RANDBETWEEN(2000,5000) -> 3511 | C18: =RANDBETWEEN(2000,5000) -> 4053 | D18: =RANDBETWEEN(2000,5000) -> 4367 | E18: =RANDBETWEEN(2000,5000) -> 3245 | F18: =RANDBETWEEN(2000,5000) -> 2720 | G18: =RANDBETWEEN(2000,5000) -> 3943 | H18: =RANDBETWEEN(2000,5000) -> 3694 | I18: =RANDBETWEEN(2000,5000) -> 4549 | J18: =RANDBETWEEN(2000,5000) -> 2697
A19: PASlR GlJDANG | B19: =RANDBETWEEN(2000,5000) -> 2841 | C19: =RANDBETWEEN(2000,5000) -> 2937 | D19: =RANDBETWEEN(2000,5000) -> 2521 | E19: =RANDBETWEEN(2000,5000) -> 2033 | F19: =RANDBETWEEN(2000,5000) -> 4101 | G19: =RANDBETWEEN(2000,5000) -> 3347 | H19: =RANDBETWEEN(2000,5000) -> 2633 | I19: =RANDBETWEEN(2000,5000) -> 4435 | J19: =RANDBETWEEN(2000,5000) -> 3599
A20: PENANG | B20: =RANDBETWEEN(2000,5000) -> 3837 | C20: =RANDBETWEEN(2000,5000) -> 3401 | D20: =RANDBETWEEN(2000,5000) -> 2979 | E20: =RANDBETWEEN(2000,5000) -> 4692 | F20: =RANDBETWEEN(2000,5000) -> 4771 | G20: =RANDBETWEEN(2000,5000) -> 2960 | H20: =RANDBETWEEN(2000,5000) -> 4315 | I20: =RANDBETWEEN(2000,5000) -> 3545 | J20: =RANDBETWEEN(2000,5000) -> 3424 | M20: usd usd 25/bl (for both 20’ and 40’box-hc)
A21: PORT KELANG | B21: =RANDBETWEEN(2000,5000) -> 4682 | C21: =RANDBETWEEN(2000,5000) -> 4175 | D21: =RANDBETWEEN(2000,5000) -> 4509 | E21: =RANDBETWEEN(2000,5000) -> 4477 | F21: =RANDBETWEEN(2000,5000) -> 3640 | G21: =RANDBETWEEN(2000,5000) -> 4977 | H21: =RANDBETWEEN(2000,5000) -> 4827 | I21: =RANDBETWEEN(2000,5000) -> 3875 | J21: =RANDBETWEEN(2000,5000) -> 4661 | M21: usd 20/20’ box - usd 40/40’ box-hc
A22: TANJlJNG PELEPAS | B22: =RANDBETWEEN(2000,5000) -> 3511 | C22: =RANDBETWEEN(2000,5000) -> 2781 | D22: =RANDBETWEEN(2000,5000) -> 3345 | E22: =RANDBETWEEN(2000,5000) -> 4333 | F22: =RANDBETWEEN(2000,5000) -> 2537 | G22: =RANDBETWEEN(2000,5000) -> 3906 | H22: =RANDBETWEEN(2000,5000) -> 4956 | I22: =RANDBETWEEN(2000,5000) -> 3667 | J22: =RANDBETWEEN(2000,5000) -> 4927 | M22: usd 50/20’box – usd 100/40’box-hc
A23: BELAWAN | B23: =RANDBETWEEN(2000,5000) -> 2116 | C23: =RANDBETWEEN(2000,5000) -> 3737 | D23: =RANDBETWEEN(2000,5000) -> 2270 | E23: =RANDBETWEEN(2000,5000) -> 2629 | F23: =RANDBETWEEN(2000,5000) -> 2957 | G23: =RANDBETWEEN(2000,5000) -> 4393 | H23: =RANDBETWEEN(2000,5000) -> 3733 | I23: =RANDBETWEEN(2000,5000) -> 2603 | J23: =RANDBETWEEN(2000,5000) -> 2594
A24: JAKARTA | B24: =RANDBETWEEN(2000,5000) -> 2305 | C24: =RANDBETWEEN(2000,5000) -> 3746 | D24: =RANDBETWEEN(2000,5000) -> 3520 | E24: =RANDBETWEEN(2000,5000) -> 4317 | F24: =RANDBETWEEN(2000,5000) -> 4119 | G24: =RANDBETWEEN(2000,5000) -> 2436 | H24: =RANDBETWEEN(2000,5000) -> 3933 | I24: =RANDBETWEEN(2000,5000) -> 4596 | J24: =RANDBETWEEN(2000,5000) -> 4999 | M24: total for 20' box | O24: 95
A25: SEMARANG | B25: =RANDBETWEEN(2000,5000) -> 3214 | C25: =RANDBETWEEN(2000,5000) -> 2009 | D25: =RANDBETWEEN(2000,5000) -> 4344 | E25: =RANDBETWEEN(2000,5000) -> 2197 | F25: =RANDBETWEEN(2000,5000) -> 4465 | G25: =RANDBETWEEN(2000,5000) -> 4590 | H25: =RANDBETWEEN(2000,5000) -> 2094 | I25: =RANDBETWEEN(2000,5000) -> 3458 | J25: =RANDBETWEEN(2000,5000) -> 2687 | M25: total for 40' box | O25: 165
A26: PANJANG | B26: =RANDBETWEEN(2000,5000) -> 2567 | C26: =RANDBETWEEN(2000,5000) -> 2216 | D26: =RANDBETWEEN(2000,5000) -> 2582 | E26: =RANDBETWEEN(2000,5000) -> 4749 | F26: =RANDBETWEEN(2000,5000) -> 4462 | G26: =RANDBETWEEN(2000,5000) -> 3132 | H26: =RANDBETWEEN(2000,5000) -> 2309 | I26: =RANDBETWEEN(2000,5000) -> 3758 | J26: =RANDBETWEEN(2000,5000) -> 3385 | M26: total for 40' box-hc | O26: 165
A27: SURABAYA | B27: =RANDBETWEEN(2000,5000) -> 2344 | C27: =RANDBETWEEN(2000,5000) -> 4508 | D27: =RANDBETWEEN(2000,5000) -> 4672 | E27: =RANDBETWEEN(2000,5000) -> 4334 | F27: =RANDBETWEEN(2000,5000) -> 3285 | G27: =RANDBETWEEN(2000,5000) -> 3478 | H27: =RANDBETWEEN(2000,5000) -> 4460 | I27: =RANDBETWEEN(2000,5000) -> 3410 | J27: =RANDBETWEEN(2000,5000) -> 2772
A28: LAEM CHABANG | B28: =RANDBETWEEN(2000,5000) -> 4455 | C28: =RANDBETWEEN(2000,5000) -> 2479 | D28: =RANDBETWEEN(2000,5000) -> 2463 | E28: =RANDBETWEEN(2000,5000) -> 4411 | F28: =RANDBETWEEN(2000,5000) -> 2942 | G28: =RANDBETWEEN(2000,5000) -> 4725 | H28: =RANDBETWEEN(2000,5000) -> 4829 | I28: =RANDBETWEEN(2000,5000) -> 4025 | J28: =RANDBETWEEN(2000,5000) -> 3596
A29: SONGKHLA | B29: =RANDBETWEEN(2000,5000) -> 4589 | C29: =RANDBETWEEN(2000,5000) -> 4907 | D29: =RANDBETWEEN(2000,5000) -> 4718 | E29: =RANDBETWEEN(2000,5000) -> 2699 | F29: =RANDBETWEEN(2000,5000) -> 2894 | G29: =RANDBETWEEN(2000,5000) -> 4588 | H29: =RANDBETWEEN(2000,5000) -> 3357 | I29: =RANDBETWEEN(2000,5000) -> 4526 | J29: =RANDBETWEEN(2000,5000) -> 3360
A30: HAlPHONG | B30: =RANDBETWEEN(2000,5000) -> 3775 | C30: =RANDBETWEEN(2000,5000) -> 2899 | D30: =RANDBETWEEN(2000,5000) -> 3806 | E30: =RANDBETWEEN(2000,5000) -> 4074 | F30: =RANDBETWEEN(2000,5000) -> 3908 | G30: =RANDBETWEEN(2000,5000) -> 2201 | H30: =RANDBETWEEN(2000,5000) -> 2367 | I30: =RANDBETWEEN(2000,5000) -> 3604 | J30: =RANDBETWEEN(2000,5000) -> 3243
A31: VlJNG | B31: =RANDBETWEEN(2000,5000) -> 3243 | C31: =RANDBETWEEN(2000,5000) -> 4050 | D31: =RANDBETWEEN(2000,5000) -> 2236 | E31: =RANDBETWEEN(2000,5000) -> 2882 | F31: =RANDBETWEEN(2000,5000) -> 2018 | G31: =RANDBETWEEN(2000,5000) -> 4578 | H31: =RANDBETWEEN(2000,5000) -> 2666 | I31: =RANDBETWEEN(2000,5000) -> 4011 | J31: =RANDBETWEEN(2000,5000) -> 4593
A32: QlJlNHON | B32: =RANDBETWEEN(2000,5000) -> 4815 | C32: =RANDBETWEEN(2000,5000) -> 3282 | D32: =RANDBETWEEN(2000,5000) -> 3730 | E32: =RANDBETWEEN(2000,5000) -> 3649 | F32: =RANDBETWEEN(2000,5000) -> 4787 | G32: =RANDBETWEEN(2000,5000) -> 3753 | H32: =RANDBETWEEN(2000,5000) -> 3239 | I32: =RANDBETWEEN(2000,5000) -> 3228 | J32: =RANDBETWEEN(2000,5000) -> 2891
A33: DA-NANG | B33: =RANDBETWEEN(2000,5000) -> 2222 | C33: =RANDBETWEEN(2000,5000) -> 2151 | D33: =RANDBETWEEN(2000,5000) -> 4200 | E33: =RANDBETWEEN(2000,5000) -> 3155 | F33: =RANDBETWEEN(2000,5000) -> 2544 | G33: =RANDBETWEEN(2000,5000) -> 3418 | H33: =RANDBETWEEN(2000,5000) -> 3268 | I33: =RANDBETWEEN(2000,5000) -> 4515 | J33: =RANDBETWEEN(2000,5000) -> 3609
A34: ΡΗΝΟΜ ΡΕΝ | B34: =RANDBETWEEN(2000,5000) -> 4151 | C34: =RANDBETWEEN(2000,5000) -> 3014 | D34: =RANDBETWEEN(2000,5000) -> 4552 | E34: =RANDBETWEEN(2000,5000) -> 3340 | F34: =RANDBETWEEN(2000,5000) -> 2079 | G34: =RANDBETWEEN(2000,5000) -> 2554 | H34: =RANDBETWEEN(2000,5000) -> 2789 | I34: =RANDBETWEEN(2000,5000) -> 3165 | J34: =RANDBETWEEN(2000,5000) -> 3869
A35: SlHANOUKVlLLE | B35: =RANDBETWEEN(2000,5000) -> 4548 | C35: =RANDBETWEEN(2000,5000) -> 4095 | D35: =RANDBETWEEN(2000,5000) -> 2777 | E35: =RANDBETWEEN(2000,5000) -> 3154 | F35: =RANDBETWEEN(2000,5000) -> 4911 | G35: =RANDBETWEEN(2000,5000) -> 2174 | H35: =RANDBETWEEN(2000,5000) -> 2701 | I35: =RANDBETWEEN(2000,5000) -> 4111 | J35: =RANDBETWEEN(2000,5000) -> 3534
A36: <ANGON | B36: =RANDBETWEEN(2000,5000) -> 2696 | C36: =RANDBETWEEN(2000,5000) -> 4567 | D36: =RANDBETWEEN(2000,5000) -> 3811 | E36: =RANDBETWEEN(2000,5000) -> 2672 | F36: =RANDBETWEEN(2000,5000) -> 2267 | G36: =RANDBETWEEN(2000,5000) -> 4587 | H36: =RANDBETWEEN(2000,5000) -> 3737 | I36: =RANDBETWEEN(2000,5000) -> 3805 | J36: =RANDBETWEEN(2000,5000) -> 2946
A37: ΜΑΝΙΙΙΑ | B37: =RANDBETWEEN(2000,5000) -> 4477 | C37: =RANDBETWEEN(2000,5000) -> 4879 | D37: =RANDBETWEEN(2000,5000) -> 3691 | E37: =RANDBETWEEN(2000,5000) -> 4674 | F37: =RANDBETWEEN(2000,5000) -> 3348 | G37: =RANDBETWEEN(2000,5000) -> 3148 | H37: =RANDBETWEEN(2000,5000) -> 3864 | I37: =RANDBETWEEN(2000,5000) -> 3010 | J37: =RANDBETWEEN(2000,5000) -> 3405
A38: BlJSAN-KRPlJS | B38: =RANDBETWEEN(2000,5000) -> 3789 | C38: =RANDBETWEEN(2000,5000) -> 3416 | D38: =RANDBETWEEN(2000,5000) -> 4286 | E38: =RANDBETWEEN(2000,5000) -> 3764 | F38: =RANDBETWEEN(2000,5000) -> 2276 | G38: =RANDBETWEEN(2000,5000) -> 2306 | H38: =RANDBETWEEN(2000,5000) -> 4591 | I38: =RANDBETWEEN(2000,5000) -> 3810 | J38: =RANDBETWEEN(2000,5000) -> 3405
... A49: ΗΑΚΑΤΑ | B49: =RANDBETWEEN(2000,5000) -> 2320 | C49: =RANDBETWEEN(2000,5000) -> 4305 | D49: =RANDBETWEEN(2000,5000) -> 4037 | E49: =RANDBETWEEN(2000,5000) -> 3982 | F49: =RANDBETWEEN(2000,5000) -> 3897 | G49: =RANDBETWEEN(2000,5000) -> 3388 | H49: =RANDBETWEEN(2000,5000) -> 3629 | I49: =RANDBETWEEN(2000,5000) -> 2574 | J49: =RANDBETWEEN(2000,5000) -> 3805

Sheet ORIGINAL B
A1: POD | B1: GENOVA | E1: LA SPEZIA | H1: VENEZIA | K1: TRIESTE | N1: RAVENNA | Q1: ANCONA | T1: BARI
A2: POL | B2: 20' | C2: 40' | D2: 40H | E2: 20' | F2: 40' | G2: 40H | H2: 20' | I2: 40' | J2: 40H | K2: 20' | L2: 40' | M2: 40H | N2: 20' | O2: 40' | P2: 40H | Q2: 20' | R2: 40' | S2: 40H | T2: 20' | U2: 40' | V2: 40H
A3: YANTIAN | B3: =RANDBETWEEN(2000,6000) -> 3025 | C3: =RANDBETWEEN(2000,6000) -> 3965 | D3: =RANDBETWEEN(2000,6000) -> 2550 | E3: =RANDBETWEEN(2000,6000) -> 5829 | F3: =RANDBETWEEN(2000,6000) -> 4932 | G3: =RANDBETWEEN(2000,6000) -> 2651 | H3: =RANDBETWEEN(2000,6000) -> 5467 | I3: =RANDBETWEEN(2000,6000) -> 5503 | ... V3: =RANDBETWEEN(2000,6000) -> 3201
A4: HONG KONG | B4: =RANDBETWEEN(2000,6000) -> 4376 | C4: =RANDBETWEEN(2000,6000) -> 4602 | D4: =RANDBETWEEN(2000,6000) -> 4962 | E4: =RANDBETWEEN(2000,6000) -> 4888 | F4: =RANDBETWEEN(2000,6000) -> 4175 | G4: =RANDBETWEEN(2000,6000) -> 5451 | H4: =RANDBETWEEN(2000,6000) -> 5222 | I4: =RANDBETWEEN(2000,6000) -> 5651 | ... V4: =RANDBETWEEN(2000,6000) -> 4070
A5: SHANGHAI | B5: =RANDBETWEEN(2000,6000) -> 4967 | C5: =RANDBETWEEN(2000,6000) -> 2695 | D5: =RANDBETWEEN(2000,6000) -> 4963 | E5: =RANDBETWEEN(2000,6000) -> 2838 | F5: =RANDBETWEEN(2000,6000) -> 4393 | G5: =RANDBETWEEN(2000,6000) -> 3985 | H5: =RANDBETWEEN(2000,6000) -> 3426 | I5: =RANDBETWEEN(2000,6000) -> 4960 | ... V5: =RANDBETWEEN(2000,6000) -> 5368
A6: NINGBO | B6: =RANDBETWEEN(2000,6000) -> 3400 | C6: =RANDBETWEEN(2000,6000) -> 5464 | D6: =RANDBETWEEN(2000,6000) -> 3345 | E6: =RANDBETWEEN(2000,6000) -> 5462 | F6: =RANDBETWEEN(2000,6000) -> 5877 | G6: =RANDBETWEEN(2000,6000) -> 5426 | H6: =RANDBETWEEN(2000,6000) -> 3003 | I6: =RANDBETWEEN(2000,6000) -> 3060 | ... V6: =RANDBETWEEN(2000,6000) -> 2891
A7: SHEKOU | B7: =RANDBETWEEN(2000,6000) -> 4207 | C7: =RANDBETWEEN(2000,6000) -> 3658 | D7: =RANDBETWEEN(2000,6000) -> 3900 | E7: =RANDBETWEEN(2000,6000) -> 3357 | F7: =RANDBETWEEN(2000,6000) -> 4797 | G7: =RANDBETWEEN(2000,6000) -> 3275 | H7: =RANDBETWEEN(2000,6000) -> 2715 | I7: =RANDBETWEEN(2000,6000) -> 4846 | ... M7: =RANDBETWEEN(2000,6000) -> 5449
A8: QINGDAO | B8: =RANDBETWEEN(2000,6000) -> 5105 | C8: =RANDBETWEEN(2000,6000) -> 5411 | D8: =RANDBETWEEN(2000,6000) -> 3848 | E8: =RANDBETWEEN(2000,6000) -> 2563 | F8: =RANDBETWEEN(2000,6000) -> 5026 | G8: =RANDBETWEEN(2000,6000) -> 4474 | H8: =RANDBETWEEN(2000,6000) -> 4308 | I8: =RANDBETWEEN(2000,6000) -> 3658 | ... V8: =RANDBETWEEN(2000,6000) -> 5847
A9: DALIAN | B9: =RANDBETWEEN(2000,6000) -> 2876 | C9: =RANDBETWEEN(2000,6000) -> 2686 | D9: =RANDBETWEEN(2000,6000) -> 4002 | E9: =RANDBETWEEN(2000,6000) -> 2715 | F9: =RANDBETWEEN(2000,6000) -> 3576 | G9: =RANDBETWEEN(2000,6000) -> 5375 | H9: =RANDBETWEEN(2000,6000) -> 3341 | I9: =RANDBETWEEN(2000,6000) -> 5232 | ... V9: =RANDBETWEEN(2000,6000) -> 5575 | X9: + Usd 104/20’ – Usd 208/40’
A10: XINGANG | B10: =RANDBETWEEN(2000,6000) -> 3812 | C10: =RANDBETWEEN(2000,6000) -> 4777 | D10: =RANDBETWEEN(2000,6000) -> 3367 | E10: =RANDBETWEEN(2000,6000) -> 4699 | F10: =RANDBETWEEN(2000,6000) -> 3377 | G10: =RANDBETWEEN(2000,6000) -> 4239 | H10: =RANDBETWEEN(2000,6000) -> 3243 | I10: =RANDBETWEEN(2000,6000) -> 3740 | ... V10: =RANDBETWEEN(2000,6000) -> 3891 | X10: + nostro profit usd 50/20’ box – usd 100/40’box-40hc
A11: XIAMEN | B11: =RANDBETWEEN(2000,6000) -> 2952 | C11: =RANDBETWEEN(2000,6000) -> 3039 | D11: =RANDBETWEEN(2000,6000) -> 4337 | E11: =RANDBETWEEN(2000,6000) -> 3191 | F11: =RANDBETWEEN(2000,6000) -> 3346 | G11: =RANDBETWEEN(2000,6000) -> 3797 | H11: =RANDBETWEEN(2000,6000) -> 5669 | I11: =RANDBETWEEN(2000,6000) -> 2645 | ... V11: =RANDBETWEEN(2000,6000) -> 5138 | X11: total for 20' box | AA11: 154
A12: NANSHA | B12: =RANDBETWEEN(2000,6000) -> 5403 | C12: =RANDBETWEEN(2000,6000) -> 3702 | D12: =RANDBETWEEN(2000,6000) -> 4844 | E12: =RANDBETWEEN(2000,6000) -> 5928 | F12: =RANDBETWEEN(2000,6000) -> 5683 | G12: =RANDBETWEEN(2000,6000) -> 5287 | H12: =RANDBETWEEN(2000,6000) -> 4057 | I12: =RANDBETWEEN(2000,6000) -> 3945 | ... V12: =RANDBETWEEN(2000,6000) -> 2373 | X12: total for 40' box | AA12: 308
A13: FUZHOU | B13: =RANDBETWEEN(2000,6000) -> 3598 | C13: =RANDBETWEEN(2000,6000) -> 3293 | D13: =RANDBETWEEN(2000,6000) -> 5900 | E13: =RANDBETWEEN(2000,6000) -> 5282 | F13: =RANDBETWEEN(2000,6000) -> 4185 | G13: =RANDBETWEEN(2000,6000) -> 5167 | H13: =RANDBETWEEN(2000,6000) -> 4134 | I13: =RANDBETWEEN(2000,6000) -> 3099 | ... V13: =RANDBETWEEN(2000,6000) -> 5538 | X13: total for 40' box-hc | AA13: 308
A14: HUANGPU | B14: =RANDBETWEEN(2000,6000) -> 2926 | C14: =RANDBETWEEN(2000,6000) -> 2724 | D14: =RANDBETWEEN(2000,6000) -> 5136 | E14: =RANDBETWEEN(2000,6000) -> 2458 | F14: =RANDBETWEEN(2000,6000) -> 4662 | G14: =RANDBETWEEN(2000,6000) -> 5410 | H14: =RANDBETWEEN(2000,6000) -> 4975 | I14: =RANDBETWEEN(2000,6000) -> 5579 | ... V14: =RANDBETWEEN(2000,6000) -> 2018
A15: JIAO XIN | B15: =RANDBETWEEN(2000,6000) -> 5079 | C15: =RANDBETWEEN(2000,6000) -> 2251 | D15: =RANDBETWEEN(2000,6000) -> 3895 | E15: =RANDBETWEEN(2000,6000) -> 2893 | F15: =RANDBETWEEN(2000,6000) -> 2231 | G15: =RANDBETWEEN(2000,6000) -> 3428 | H15: =RANDBETWEEN(2000,6000) -> 2202 | I15: =RANDBETWEEN(2000,6000) -> 4939 | ... V15: =RANDBETWEEN(2000,6000) -> 2854
A16: JIUJIANG, GAOMING | B16: =RANDBETWEEN(2000,6000) -> 5230 | C16: =RANDBETWEEN(2000,6000) -> 4556 | D16: =RANDBETWEEN(2000,6000) -> 2861 | E16: =RANDBETWEEN(2000,6000) -> 2244 | F16: =RANDBETWEEN(2000,6000) -> 2969 | G16: =RANDBETWEEN(2000,6000) -> 4090 | H16: =RANDBETWEEN(2000,6000) -> 2301 | I16: =RANDBETWEEN(2000,6000) -> 2061 | ... V16: =RANDBETWEEN(2000,6000) -> 3553
A17: NANHAI, SANSHUI | B17: =RANDBETWEEN(2000,6000) -> 2756 | C17: =RANDBETWEEN(2000,6000) -> 4429 | D17: =RANDBETWEEN(2000,6000) -> 4226 | E17: =RANDBETWEEN(2000,6000) -> 5823 | F17: =RANDBETWEEN(2000,6000) -> 4339 | G17: =RANDBETWEEN(2000,6000) -> 4845 | H17: =RANDBETWEEN(2000,6000) -> 5481 | I17: =RANDBETWEEN(2000,6000) -> 4868 | ... V17: =RANDBETWEEN(2000,6000) -> 5490
A18: JIANGMEN | B18: =RANDBETWEEN(2000,6000) -> 2936 | C18: =RANDBETWEEN(2000,6000) -> 5534 | D18: =RANDBETWEEN(2000,6000) -> 5793 | E18: =RANDBETWEEN(2000,6000) -> 4975 | F18: =RANDBETWEEN(2000,6000) -> 4793 | G18: =RANDBETWEEN(2000,6000) -> 4816 | H18: =RANDBETWEEN(2000,6000) -> 5902 | I18: =RANDBETWEEN(2000,6000) -> 4053 | ... V18: =RANDBETWEEN(2000,6000) -> 3235
A19: SHANTOU | B19: =RANDBETWEEN(2000,6000) -> 2782 | C19: =RANDBETWEEN(2000,6000) -> 5050 | D19: =RANDBETWEEN(2000,6000) -> 2317 | E19: =RANDBETWEEN(2000,6000) -> 4938 | F19: =RANDBETWEEN(2000,6000) -> 5876 | G19: =RANDBETWEEN(2000,6000) -> 4573 | H19: =RANDBETWEEN(2000,6000) -> 3746 | I19: =RANDBETWEEN(2000,6000) -> 2177 | ... V19: =RANDBETWEEN(2000,6000) -> 3433
A20: TAIZHOU | B20: =RANDBETWEEN(2000,6000) -> 2308 | C20: =RANDBETWEEN(2000,6000) -> 5618 | D20: =RANDBETWEEN(2000,6000) -> 4885 | E20: =RANDBETWEEN(2000,6000) -> 2878 | F20: =RANDBETWEEN(2000,6000) -> 5982 | G20: =RANDBETWEEN(2000,6000) -> 5677 | H20: =RANDBETWEEN(2000,6000) -> 5164 | I20: =RANDBETWEEN(2000,6000) -> 3825 | ... V20: =RANDBETWEEN(2000,6000) -> 5280
A21: WUHAN | B21: =RANDBETWEEN(2000,6000) -> 5017 | C21: =RANDBETWEEN(2000,6000) -> 5010 | D21: =RANDBETWEEN(2000,6000) -> 2795 | E21: =RANDBETWEEN(2000,6000) -> 2363 | F21: =RANDBETWEEN(2000,6000) -> 4707 | G21: =RANDBETWEEN(2000,6000) -> 2453 | H21: =RANDBETWEEN(2000,6000) -> 4292 | I21: =RANDBETWEEN(2000,6000) -> 3666 | ... V21: =RANDBETWEEN(2000,6000) -> 3483
A22: XIAO LAN | B22: =RANDBETWEEN(2000,6000) -> 4589 | C22: =RANDBETWEEN(2000,6000) -> 5698 | D22: =RANDBETWEEN(2000,6000) -> 5573 | E22: =RANDBETWEEN(2000,6000) -> 2248 | F22: =RANDBETWEEN(2000,6000) -> 4465 | G22: =RANDBETWEEN(2000,6000) -> 2971 | H22: =RANDBETWEEN(2000,6000) -> 4735 | I22: =RANDBETWEEN(2000,6000) -> 5295 | ... V22: =RANDBETWEEN(2000,6000) -> 3604
A23: ZHAN JIANG | B23: =RANDBETWEEN(2000,6000) -> 4727 | C23: =RANDBETWEEN(2000,6000) -> 5572 | D23: =RANDBETWEEN(2000,6000) -> 4641 | E23: =RANDBETWEEN(2000,6000) -> 3871 | F23: =RANDBETWEEN(2000,6000) -> 3569 | G23: =RANDBETWEEN(2000,6000) -> 5505 | H23: =RANDBETWEEN(2000,6000) -> 5403 | I23: =RANDBETWEEN(2000,6000) -> 4364 | ... V23: =RANDBETWEEN(2000,6000) -> 4164
A24: ZHAO QING | B24: =RANDBETWEEN(2000,6000) -> 2548 | C24: =RANDBETWEEN(2000,6000) -> 4149 | D24: =RANDBETWEEN(2000,6000) -> 4759 | E24: =RANDBETWEEN(2000,6000) -> 3147 | F24: =RANDBETWEEN(2000,6000) -> 2400 | G24: =RANDBETWEEN(2000,6000) -> 4986 | H24: =RANDBETWEEN(2000,6000) -> 3242 | I24: =RANDBETWEEN(2000,6000) -> 2491 | ... V24: =RANDBETWEEN(2000,6000) -> 2163
A25: LIANYUNGANG | B25: =RANDBETWEEN(2000,6000) -> 4293 | C25: =RANDBETWEEN(2000,6000) -> 5616 | D25: =RANDBETWEEN(2000,6000) -> 2365 | E25: =RANDBETWEEN(2000,6000) -> 5247 | F25: =RANDBETWEEN(2000,6000) -> 2038 | G25: =RANDBETWEEN(2000,6000) -> 2425 | H25: =RANDBETWEEN(2000,6000) -> 4257 | I25: =RANDBETWEEN(2000,6000) -> 5858 | ... V25: =RANDBETWEEN(2000,6000) -> 3650
... A80: CHENNAI | B80: =RANDBETWEEN(2000,6000) -> 4129 | C80: =RANDBETWEEN(2000,6000) -> 4081 | D80: =RANDBETWEEN(2000,6000) -> 4404 | E80: =RANDBETWEEN(2000,6000) -> 4449 | F80: =RANDBETWEEN(2000,6000) -> 5577 | G80: =RANDBETWEEN(2000,6000) -> 3037 | H80: =RANDBETWEEN(2000,6000) -> 4395 | I80: =RANDBETWEEN(2000,6000) -> 2671 | ... V80: =RANDBETWEEN(2000,6000) -> 4561

Sheet ORIGINAL C
A1: ORIGIN | B1: GENOA / LA SPEZIA | E1: NAP/LIV/VCE/SAL/AOI
A2: Port of Loading | B2: 20' | C2: 40' | D2: 40H | E2: 20' | F2: 40' | G2: 40H
A3: Chattogram | B3: =RANDBETWEEN(2000,5000) -> 3021 | C3: =RANDBETWEEN(2000,5000) -> 3672 | D3: =RANDBETWEEN(2000,5000) -> 3890 | E3: =RANDBETWEEN(2000,5000) -> 3446 | F3: =RANDBETWEEN(2000,5000) -> 3022 | G3: =RANDBETWEEN(2000,5000) -> 3572
A4: DHAKA | B4: =RANDBETWEEN(2000,5000) -> 4537 | C4: =RANDBETWEEN(2000,5000) -> 3314 | D4: =RANDBETWEEN(2000,5000) -> 4803 | E4: =RANDBETWEEN(2000,5000) -> 4244 | F4: =RANDBETWEEN(2000,5000) -> 4139 | G4: =RANDBETWEEN(2000,5000) -> 4302
A5: ANQING | B5: =RANDBETWEEN(2000,5000) -> 4305 | C5: =RANDBETWEEN(2000,5000) -> 4307 | D5: =RANDBETWEEN(2000,5000) -> 4094 | E5: =RANDBETWEEN(2000,5000) -> 3414 | F5: =RANDBETWEEN(2000,5000) -> 2140 | G5: =RANDBETWEEN(2000,5000) -> 4996
A6: BEIJIAO,SHUNDE | B6: =RANDBETWEEN(2000,5000) -> 2205 | C6: =RANDBETWEEN(2000,5000) -> 3459 | D6: =RANDBETWEEN(2000,5000) -> 2796 | E6: =RANDBETWEEN(2000,5000) -> 4433 | F6: =RANDBETWEEN(2000,5000) -> 2975 | G6: =RANDBETWEEN(2000,5000) -> 2612 | I6: + USD 30/20’-40’-40HC
A7: CHONGQING | B7: =RANDBETWEEN(2000,5000) -> 3570 | C7: =RANDBETWEEN(2000,5000) -> 3088 | D7: =RANDBETWEEN(2000,5000) -> 3528 | E7: =RANDBETWEEN(2000,5000) -> 4832 | F7: =RANDBETWEEN(2000,5000) -> 4646 | G7: =RANDBETWEEN(2000,5000) -> 2112 | I7: + USD 8/20’ – USD 16/40’-40HC
A8: CHANGSHA | B8: =RANDBETWEEN(2000,5000) -> 4792 | C8: =RANDBETWEEN(2000,5000) -> 2796 | D8: =RANDBETWEEN(2000,5000) -> 2433 | E8: =RANDBETWEEN(2000,5000) -> 4684 | F8: =RANDBETWEEN(2000,5000) -> 2139 | G8: =RANDBETWEEN(2000,5000) -> 2751 | I8: + ns profit USD 50/20’ – USD 100/40’-40HC
A9: CHANGZHOU | B9: =RANDBETWEEN(2000,5000) -> 3590 | C9: =RANDBETWEEN(2000,5000) -> 4943 | D9: =RANDBETWEEN(2000,5000) -> 4385 | E9: =RANDBETWEEN(2000,5000) -> 3517 | F9: =RANDBETWEEN(2000,5000) -> 4837 | G9: =RANDBETWEEN(2000,5000) -> 3501 | I9: total for 20' box | J9: 88
A10: DALIAN,LN | B10: =RANDBETWEEN(2000,5000) -> 3164 | C10: =RANDBETWEEN(2000,5000) -> 2616 | D10: =RANDBETWEEN(2000,5000) -> 3970 | E10: =RANDBETWEEN(2000,5000) -> 4584 | F10: =RANDBETWEEN(2000,5000) -> 3910 | G10: =RANDBETWEEN(2000,5000) -> 4015 | I10: total for 40' box | J10: 146
A11: FUZHOU | B11: =RANDBETWEEN(2000,5000) -> 3521 | C11: =RANDBETWEEN(2000,5000) -> 3654 | D11: =RANDBETWEEN(2000,5000) -> 4861 | E11: =RANDBETWEEN(2000,5000) -> 3007 | F11: =RANDBETWEEN(2000,5000) -> 4299 | G11: =RANDBETWEEN(2000,5000) -> 4014 | I11: total for 40' box-hc | J11: 146
A12: GAOMING | B12: =RANDBETWEEN(2000,5000) -> 2171 | C12: =RANDBETWEEN(2000,5000) -> 3715 | D12: =RANDBETWEEN(2000,5000) -> 2911 | E12: =RANDBETWEEN(2000,5000) -> 2689 | F12: =RANDBETWEEN(2000,5000) -> 2822 | G12: =RANDBETWEEN(2000,5000) -> 4352
A13: HUANGPU | B13: =RANDBETWEEN(2000,5000) -> 2289 | C13: =RANDBETWEEN(2000,5000) -> 2827 | D13: =RANDBETWEEN(2000,5000) -> 2291 | E13: =RANDBETWEEN(2000,5000) -> 3244 | F13: =RANDBETWEEN(2000,5000) -> 4629 | G13: =RANDBETWEEN(2000,5000) -> 2177
A14: JIAOXIN | B14: =RANDBETWEEN(2000,5000) -> 4954 | C14: =RANDBETWEEN(2000,5000) -> 3298 | D14: =RANDBETWEEN(2000,5000) -> 2061 | E14: =RANDBETWEEN(2000,5000) -> 2095 | F14: =RANDBETWEEN(2000,5000) -> 2770 | G14: =RANDBETWEEN(2000,5000) -> 2571
A15: JIANGMEN | B15: =RANDBETWEEN(2000,5000) -> 4060 | C15: =RANDBETWEEN(2000,5000) -> 3864 | D15: =RANDBETWEEN(2000,5000) -> 2027 | E15: =RANDBETWEEN(2000,5000) -> 3000 | F15: =RANDBETWEEN(2000,5000) -> 4375 | G15: =RANDBETWEEN(2000,5000) -> 4367
A16: JIUJIANG | B16: =RANDBETWEEN(2000,5000) -> 3618 | C16: =RANDBETWEEN(2000,5000) -> 4132 | D16: =RANDBETWEEN(2000,5000) -> 4736 | E16: =RANDBETWEEN(2000,5000) -> 2420 | F16: =RANDBETWEEN(2000,5000) -> 3484 | G16: =RANDBETWEEN(2000,5000) -> 2384
A17: NANCHANG | B17: =RANDBETWEEN(2000,5000) -> 2218 | C17: =RANDBETWEEN(2000,5000) -> 4547 | D17: =RANDBETWEEN(2000,5000) -> 4878 | E17: =RANDBETWEEN(2000,5000) -> 2287 | F17: =RANDBETWEEN(2000,5000) -> 4139 | G17: =RANDBETWEEN(2000,5000) -> 2478
A18: LELIU,SHUNDE | B18: =RANDBETWEEN(2000,5000) -> 3410 | C18: =RANDBETWEEN(2000,5000) -> 2446 | D18: =RANDBETWEEN(2000,5000) -> 2738 | E18: =RANDBETWEEN(2000,5000) -> 3884 | F18: =RANDBETWEEN(2000,5000) -> 3043 | G18: =RANDBETWEEN(2000,5000) -> 2619
A19: LIANYUNGANG | B19: =RANDBETWEEN(2000,5000) -> 4887 | C19: =RANDBETWEEN(2000,5000) -> 3586 | D19: =RANDBETWEEN(2000,5000) -> 2713 | E19: =RANDBETWEEN(2000,5000) -> 3980 | F19: =RANDBETWEEN(2000,5000) -> 4016 | G19: =RANDBETWEEN(2000,5000) -> 2770
A20: NINGBO | B20: =RANDBETWEEN(2000,5000) -> 3773 | C20: =RANDBETWEEN(2000,5000) -> 3276 | D20: =RANDBETWEEN(2000,5000) -> 4480 | E20: =RANDBETWEEN(2000,5000) -> 4237 | F20: =RANDBETWEEN(2000,5000) -> 4528 | G20: =RANDBETWEEN(2000,5000) -> 3490
A21: NANJING | B21: =RANDBETWEEN(2000,5000) -> 3110 | C21: =RANDBETWEEN(2000,5000) -> 3352 | D21: =RANDBETWEEN(2000,5000) -> 4974 | E21: =RANDBETWEEN(2000,5000) -> 3637 | F21: =RANDBETWEEN(2000,5000) -> 2343 | G21: =RANDBETWEEN(2000,5000) -> 4180
A22: NANTONG | B22: =RANDBETWEEN(2000,5000) -> 3955 | C22: =RANDBETWEEN(2000,5000) -> 2244 | D22: =RANDBETWEEN(2000,5000) -> 3954 | E22: =RANDBETWEEN(2000,5000) -> 2339 | F22: =RANDBETWEEN(2000,5000) -> 2794 | G22: =RANDBETWEEN(2000,5000) -> 2393
A23: NANSHA NEW PORT | B23: =RANDBETWEEN(2000,5000) -> 3662 | C23: =RANDBETWEEN(2000,5000) -> 2332 | D23: =RANDBETWEEN(2000,5000) -> 4262 | E23: =RANDBETWEEN(2000,5000) -> 3972 | F23: =RANDBETWEEN(2000,5000) -> 4223 | G23: =RANDBETWEEN(2000,5000) -> 4113
... A73: HAIPHONG | B73: =RANDBETWEEN(2000,5000) -> 4664 | C73: =RANDBETWEEN(2000,5000) -> 4226 | D73: =RANDBETWEEN(2000,5000) -> 2565 | E73: =RANDBETWEEN(2000,5000) -> 2640 | F73: =RANDBETWEEN(2000,5000) -> 4502 | G73: =RANDBETWEEN(2000,5000) -> 3350

Sheet SOLUTION
A1: Formule | B1: Strumenti
A2: cerca vert((confronta)) | B2: convalida dati
A3: se((somma )) | B3: formattazione condizionale
A4: se((se(somma))) | B4: protezione foglio
A5: se((cerca vert (confronta)))

Sheet A
A1: PORTS OF LOADING | B1: PORTS OF DISCHARGE | M1: PORTS OF DISCHARGE | N1: Transport Additional surcharge (TAD) in USD on top of Gioia Tauro rates
N3: 20' GT | O3: 40' GT | P3: 40H GT
B4: Genoa, La Spezia | E4: Trieste | H4: Gioia Tauro | M4: LEGHORN | N4: 0 | O4: 0 | P4: 0
B5: 20' GS | C5: 40' GS | D5: 40H GS | E5: 20' T | F5: 40' T | G5: 40H T | H5: 20' GT | I5: 40' GT | J5: 40H GT | M5: CIVITAVECCHIA | N5: 0 | O5: 0 | P5: 0
A6: HONG KONG | B6: =RANDBETWEEN(2000,5000) -> 4048 | C6: =RANDBETWEEN(2000,5000) -> 3783 | D6: =RANDBETWEEN(2000,5000) -> 2580 | E6: =RANDBETWEEN(2000,5000) -> 3943 | F6: =RANDBETWEEN(2000,5000) -> 4101 | G6: =RANDBETWEEN(2000,5000) -> 3527 | H6: =RANDBETWEEN(2000,5000) -> 2660 | I6: =RANDBETWEEN(2000,5000) -> 3487 | J6: =RANDBETWEEN(2000,5000) -> 4547 | M6: NAPLES | N6: 0 | O6: 0 | P6: 0
A7: SHEKOU | B7: =RANDBETWEEN(2000,5000) -> 3694 | C7: =RANDBETWEEN(2000,5000) -> 3939 | D7: =RANDBETWEEN(2000,5000) -> 2448 | E7: =RANDBETWEEN(2000,5000) -> 2113 | F7: =RANDBETWEEN(2000,5000) -> 2037 | G7: =RANDBETWEEN(2000,5000) -> 4157 | H7: =RANDBETWEEN(2000,5000) -> 3785 | I7: =RANDBETWEEN(2000,5000) -> 3590 | J7: =RANDBETWEEN(2000,5000) -> 4243 | M7: SALERNO | N7: =RANDBETWEEN(50,1000) -> 562 | O7: =RANDBETWEEN(50,1000) -> 751 | P7: =RANDBETWEEN(50,1000) -> 297
A8: YANTlAN | B8: =RANDBETWEEN(2000,5000) -> 3262 | C8: =RANDBETWEEN(2000,5000) -> 4461 | D8: =RANDBETWEEN(2000,5000) -> 4177 | E8: =RANDBETWEEN(2000,5000) -> 2376 | F8: =RANDBETWEEN(2000,5000) -> 4896 | G8: =RANDBETWEEN(2000,5000) -> 2092 | H8: =RANDBETWEEN(2000,5000) -> 2989 | I8: =RANDBETWEEN(2000,5000) -> 3588 | J8: =RANDBETWEEN(2000,5000) -> 3857 | M8: RAVENNA | N8: =RANDBETWEEN(50,1000) -> 706 | O8: =RANDBETWEEN(50,1000) -> 196 | P8: =RANDBETWEEN(50,1000) -> 271
A9: NANSHA | B9: =RANDBETWEEN(2000,5000) -> 3148 | C9: =RANDBETWEEN(2000,5000) -> 4102 | D9: =RANDBETWEEN(2000,5000) -> 4763 | E9: =RANDBETWEEN(2000,5000) -> 3530 | F9: =RANDBETWEEN(2000,5000) -> 3153 | G9: =RANDBETWEEN(2000,5000) -> 2771 | H9: =RANDBETWEEN(2000,5000) -> 3184 | I9: =RANDBETWEEN(2000,5000) -> 4483 | J9: =RANDBETWEEN(2000,5000) -> 2909 | M9: VENICE | N9: =RANDBETWEEN(50,1000) -> 840 | O9: =RANDBETWEEN(50,1000) -> 153 | P9: =RANDBETWEEN(50,1000) -> 232
A10: XIAMEN | B10: =RANDBETWEEN(2000,5000) -> 2083 | C10: =RANDBETWEEN(2000,5000) -> 3503 | D10: =RANDBETWEEN(2000,5000) -> 3491 | E10: =RANDBETWEEN(2000,5000) -> 4285 | F10: =RANDBETWEEN(2000,5000) -> 3222 | G10: =RANDBETWEEN(2000,5000) -> 4584 | H10: =RANDBETWEEN(2000,5000) -> 2369 | I10: =RANDBETWEEN(2000,5000) -> 4765 | J10: =RANDBETWEEN(2000,5000) -> 3187 | M10: ANCONA | N10: =RANDBETWEEN(50,1000) -> 866 | O10: =RANDBETWEEN(50,1000) -> 746 | P10: =RANDBETWEEN(50,1000) -> 974
A11: FlJZHOlJ | B11: =RANDBETWEEN(2000,5000) -> 2417 | C11: =RANDBETWEEN(2000,5000) -> 4909 | D11: =RANDBETWEEN(2000,5000) -> 3500 | E11: =RANDBETWEEN(2000,5000) -> 2203 | F11: =RANDBETWEEN(2000,5000) -> 3518 | G11: =RANDBETWEEN(2000,5000) -> 4015 | H11: =RANDBETWEEN(2000,5000) -> 2510 | I11: =RANDBETWEEN(2000,5000) -> 4318 | J11: =RANDBETWEEN(2000,5000) -> 4385 | M11: BARI | N11: =RANDBETWEEN(50,1000) -> 298 | O11: =RANDBETWEEN(50,1000) -> 60 | P11: =RANDBETWEEN(50,1000) -> 151
A12: SHANTOU | B12: =RANDBETWEEN(2000,5000) -> 3792 | C12: =RANDBETWEEN(2000,5000) -> 3801 | D12: =RANDBETWEEN(2000,5000) -> 3853 | E12: =RANDBETWEEN(2000,5000) -> 2492 | F12: =RANDBETWEEN(2000,5000) -> 2900 | G12: =RANDBETWEEN(2000,5000) -> 2790 | H12: =RANDBETWEEN(2000,5000) -> 3456 | I12: =RANDBETWEEN(2000,5000) -> 3223 | J12: =RANDBETWEEN(2000,5000) -> 3303 | M12: AUGUSTA | N12: =RANDBETWEEN(50,1000) -> 52 | O12: =RANDBETWEEN(50,1000) -> 536 | P12: =RANDBETWEEN(50,1000) -> 260
A13: QINZHOU | B13: =RANDBETWEEN(2000,5000) -> 4984 | C13: =RANDBETWEEN(2000,5000) -> 4713 | D13: =RANDBETWEEN(2000,5000) -> 3325 | E13: =RANDBETWEEN(2000,5000) -> 2905 | F13: =RANDBETWEEN(2000,5000) -> 4878 | G13: =RANDBETWEEN(2000,5000) -> 3766 | H13: =RANDBETWEEN(2000,5000) -> 2645 | I13: =RANDBETWEEN(2000,5000) -> 3806 | J13: =RANDBETWEEN(2000,5000) -> 2038 | M13: POZZALLO | N13: =RANDBETWEEN(50,1000) -> 810 | O13: =RANDBETWEEN(50,1000) -> 944 | P13: =RANDBETWEEN(50,1000) -> 288
A14: SHANGHAl | B14: =RANDBETWEEN(2000,5000) -> 2307 | C14: =RANDBETWEEN(2000,5000) -> 4217 | D14: =RANDBETWEEN(2000,5000) -> 4535 | E14: =RANDBETWEEN(2000,5000) -> 3413 | F14: =RANDBETWEEN(2000,5000) -> 4801 | G14: =RANDBETWEEN(2000,5000) -> 2133 | H14: =RANDBETWEEN(2000,5000) -> 3314 | I14: =RANDBETWEEN(2000,5000) -> 4622 | J14: =RANDBETWEEN(2000,5000) -> 2509 | M14: PALERMO | N14: =RANDBETWEEN(50,1000) -> 726 | O14: =RANDBETWEEN(50,1000) -> 638 | P14: =RANDBETWEEN(50,1000) -> 319
A15: NlNGBO | B15: =RANDBETWEEN(2000,5000) -> 2557 | C15: =RANDBETWEEN(2000,5000) -> 4505 | D15: =RANDBETWEEN(2000,5000) -> 4672 | E15: =RANDBETWEEN(2000,5000) -> 3938 | F15: =RANDBETWEEN(2000,5000) -> 3732 | G15: =RANDBETWEEN(2000,5000) -> 4285 | H15: =RANDBETWEEN(2000,5000) -> 4225 | I15: =RANDBETWEEN(2000,5000) -> 2445 | J15: =RANDBETWEEN(2000,5000) -> 3266 | M15: CAGLIARI | N15: =RANDBETWEEN(50,1000) -> 754 | O15: =RANDBETWEEN(50,1000) -> 203 | P15: =RANDBETWEEN(50,1000) -> 856
A16: QINGDAO | B16: =RANDBETWEEN(2000,5000) -> 4894 | C16: =RANDBETWEEN(2000,5000) -> 2487 | D16: =RANDBETWEEN(2000,5000) -> 3160 | E16: =RANDBETWEEN(2000,5000) -> 2340 | F16: =RANDBETWEEN(2000,5000) -> 3779 | G16: =RANDBETWEEN(2000,5000) -> 3560 | H16: =RANDBETWEEN(2000,5000) -> 2688 | I16: =RANDBETWEEN(2000,5000) -> 2122 | J16: =RANDBETWEEN(2000,5000) -> 2934
A17: XINGANG | B17: =RANDBETWEEN(2000,5000) -> 3528 | C17: =RANDBETWEEN(2000,5000) -> 4144 | D17: =RANDBETWEEN(2000,5000) -> 2577 | E17: =RANDBETWEEN(2000,5000) -> 2121 | F17: =RANDBETWEEN(2000,5000) -> 4777 | G17: =RANDBETWEEN(2000,5000) -> 3444 | H17: =RANDBETWEEN(2000,5000) -> 2863 | I17: =RANDBETWEEN(2000,5000) -> 4554 | J17: =RANDBETWEEN(2000,5000) -> 3493
A18: DALlAN | B18: =RANDBETWEEN(2000,5000) -> 4771 | C18: =RANDBETWEEN(2000,5000) -> 4062 | D18: =RANDBETWEEN(2000,5000) -> 4848 | E18: =RANDBETWEEN(2000,5000) -> 3093 | F18: =RANDBETWEEN(2000,5000) -> 2747 | G18: =RANDBETWEEN(2000,5000) -> 3516 | H18: =RANDBETWEEN(2000,5000) -> 3540 | I18: =RANDBETWEEN(2000,5000) -> 3637 | J18: =RANDBETWEEN(2000,5000) -> 4529 | M18: 40' GT | Q18: usd usd 25/bl (for both 20’ and 40’box-hc)
A19: PASlR GlJDANG | B19: =RANDBETWEEN(2000,5000) -> 2612 | C19: =RANDBETWEEN(2000,5000) -> 3238 | D19: =RANDBETWEEN(2000,5000) -> 2767 | E19: =RANDBETWEEN(2000,5000) -> 2181 | F19: =RANDBETWEEN(2000,5000) -> 2402 | G19: =RANDBETWEEN(2000,5000) -> 4765 | H19: =RANDBETWEEN(2000,5000) -> 2759 | I19: =RANDBETWEEN(2000,5000) -> 3406 | J19: =RANDBETWEEN(2000,5000) -> 4544 | M19: NAPLES | Q19: usd 20/20’ box - usd 40/40’ box-hc
A20: PENANG | B20: =RANDBETWEEN(2000,5000) -> 3491 | C20: =RANDBETWEEN(2000,5000) -> 2085 | D20: =RANDBETWEEN(2000,5000) -> 4203 | E20: =RANDBETWEEN(2000,5000) -> 3686 | F20: =RANDBETWEEN(2000,5000) -> 2011 | G20: =RANDBETWEEN(2000,5000) -> 4721 | H20: =RANDBETWEEN(2000,5000) -> 3788 | I20: =RANDBETWEEN(2000,5000) -> 4695 | J20: =RANDBETWEEN(2000,5000) -> 4993 | Q20: usd 50/20’box – usd 100/40’box-hc
A21: PORT KELANG | B21: =RANDBETWEEN(2000,5000) -> 4404 | C21: =RANDBETWEEN(2000,5000) -> 4070 | D21: =RANDBETWEEN(2000,5000) -> 4715 | E21: =RANDBETWEEN(2000,5000) -> 3818 | F21: =RANDBETWEEN(2000,5000) -> 2702 | G21: =RANDBETWEEN(2000,5000) -> 3951 | H21: =RANDBETWEEN(2000,5000) -> 4199 | I21: =RANDBETWEEN(2000,5000) -> 4823 | J21: =RANDBETWEEN(2000,5000) -> 2710
A22: TANJlJNG PELEPAS | B22: =RANDBETWEEN(2000,5000) -> 2487 | C22: =RANDBETWEEN(2000,5000) -> 4971 | D22: =RANDBETWEEN(2000,5000) -> 3315 | E22: =RANDBETWEEN(2000,5000) -> 4092 | F22: =RANDBETWEEN(2000,5000) -> 4449 | G22: =RANDBETWEEN(2000,5000) -> 2122 | H22: =RANDBETWEEN(2000,5000) -> 2448 | I22: =RANDBETWEEN(2000,5000) -> 4643 | J22: =RANDBETWEEN(2000,5000) -> 4534 | M22: 20' T | Q22: total for 20' box | S22: 95
A23: BELAWAN | B23: =RANDBETWEEN(2000,5000) -> 4214 | C23: =RANDBETWEEN(2000,5000) -> 3605 | D23: =RANDBETWEEN(2000,5000) -> 4859 | E23: =RANDBETWEEN(2000,5000) -> 3629 | F23: =RANDBETWEEN(2000,5000) -> 2455 | G23: =RANDBETWEEN(2000,5000) -> 4974 | H23: =RANDBETWEEN(2000,5000) -> 4286 | I23: =RANDBETWEEN(2000,5000) -> 2560 | J23: =RANDBETWEEN(2000,5000) -> 2049 | M23: QINZHOU | Q23: total for 40' box | S23: 165
A24: JAKARTA | B24: =RANDBETWEEN(2000,5000) -> 3229 | C24: =RANDBETWEEN(2000,5000) -> 2770 | D24: =RANDBETWEEN(2000,5000) -> 4720 | E24: =RANDBETWEEN(2000,5000) -> 4974 | F24: =RANDBETWEEN(2000,5000) -> 2658 | G24: =RANDBETWEEN(2000,5000) -> 2348 | H24: =RANDBETWEEN(2000,5000) -> 3297 | I24: =RANDBETWEEN(2000,5000) -> 4367 | J24: =RANDBETWEEN(2000,5000) -> 3525 | Q24: total for 40' box-hc | S24: 165
A25: SEMARANG | B25: =RANDBETWEEN(2000,5000) -> 4271 | C25: =RANDBETWEEN(2000,5000) -> 3010 | D25: =RANDBETWEEN(2000,5000) -> 4241 | E25: =RANDBETWEEN(2000,5000) -> 4760 | F25: =RANDBETWEEN(2000,5000) -> 3646 | G25: =RANDBETWEEN(2000,5000) -> 3462 | H25: =RANDBETWEEN(2000,5000) -> 4017 | I25: =RANDBETWEEN(2000,5000) -> 3553 | J25: =RANDBETWEEN(2000,5000) -> 3011
A26: PANJANG | B26: =RANDBETWEEN(2000,5000) -> 4402 | C26: =RANDBETWEEN(2000,5000) -> 4705 | D26: =RANDBETWEEN(2000,5000) -> 4876 | E26: =RANDBETWEEN(2000,5000) -> 4419 | F26: =RANDBETWEEN(2000,5000) -> 4213 | G26: =RANDBETWEEN(2000,5000) -> 4746 | H26: =RANDBETWEEN(2000,5000) -> 4741 | I26: =RANDBETWEEN(2000,5000) -> 3542 | J26: =RANDBETWEEN(2000,5000) -> 3640 | Q26: =IF(M18=M22,VLOOKUP($M$19,$M$4:$P$15,MATCH($M$18,$M$3:$P$3,0),FALSE),"POD IS NOT AT GIOIA TOURO PORT") -> POD IS NOT AT GIOIA TOURO PORT
A27: SURABAYA | B27: =RANDBETWEEN(2000,5000) -> 3132 | C27: =RANDBETWEEN(2000,5000) -> 3298 | D27: =RANDBETWEEN(2000,5000) -> 2373 | E27: =RANDBETWEEN(2000,5000) -> 2761 | F27: =RANDBETWEEN(2000,5000) -> 2242 | G27: =RANDBETWEEN(2000,5000) -> 4117 | H27: =RANDBETWEEN(2000,5000) -> 4394 | I27: =RANDBETWEEN(2000,5000) -> 4538 | J27: =RANDBETWEEN(2000,5000) -> 4694
A28: LAEM CHABANG | B28: =RANDBETWEEN(2000,5000) -> 2751 | C28: =RANDBETWEEN(2000,5000) -> 2174 | D28: =RANDBETWEEN(2000,5000) -> 4292 | E28: =RANDBETWEEN(2000,5000) -> 4054 | F28: =RANDBETWEEN(2000,5000) -> 3349 | G28: =RANDBETWEEN(2000,5000) -> 4322 | H28: =RANDBETWEEN(2000,5000) -> 3722 | I28: =RANDBETWEEN(2000,5000) -> 4047 | J28: =RANDBETWEEN(2000,5000) -> 4374 | Q28: =VLOOKUP(M23,A5:J53,MATCH(M22,A5:J5,0),FALSE) -> 2905
A29: SONGKHLA | B29: =RANDBETWEEN(2000,5000) -> 3452 | C29: =RANDBETWEEN(2000,5000) -> 2368 | D29: =RANDBETWEEN(2000,5000) -> 4956 | E29: =RANDBETWEEN(2000,5000) -> 3254 | F29: =RANDBETWEEN(2000,5000) -> 2164 | G29: =RANDBETWEEN(2000,5000) -> 4121 | H29: =RANDBETWEEN(2000,5000) -> 3404 | I29: =RANDBETWEEN(2000,5000) -> 3344 | J29: =RANDBETWEEN(2000,5000) -> 4484
A30: HAlPHONG | B30: =RANDBETWEEN(2000,5000) -> 4625 | C30: =RANDBETWEEN(2000,5000) -> 3247 | D30: =RANDBETWEEN(2000,5000) -> 4890 | E30: =RANDBETWEEN(2000,5000) -> 3256 | F30: =RANDBETWEEN(2000,5000) -> 3826 | G30: =RANDBETWEEN(2000,5000) -> 3440 | H30: =RANDBETWEEN(2000,5000) -> 2777 | I30: =RANDBETWEEN(2000,5000) -> 4272 | J30: =RANDBETWEEN(2000,5000) -> 3605
A31: VlJNG | B31: =RANDBETWEEN(2000,5000) -> 3769 | C31: =RANDBETWEEN(2000,5000) -> 2180 | D31: =RANDBETWEEN(2000,5000) -> 3832 | E31: =RANDBETWEEN(2000,5000) -> 2727 | F31: =RANDBETWEEN(2000,5000) -> 2200 | G31: =RANDBETWEEN(2000,5000) -> 3116 | H31: =RANDBETWEEN(2000,5000) -> 4779 | I31: =RANDBETWEEN(2000,5000) -> 2664 | J31: =RANDBETWEEN(2000,5000) -> 2572
A32: QlJlNHON | B32: =RANDBETWEEN(2000,5000) -> 2472 | C32: =RANDBETWEEN(2000,5000) -> 2507 | D32: =RANDBETWEEN(2000,5000) -> 2070 | E32: =RANDBETWEEN(2000,5000) -> 3256 | F32: =RANDBETWEEN(2000,5000) -> 2779 | G32: =RANDBETWEEN(2000,5000) -> 4178 | H32: =RANDBETWEEN(2000,5000) -> 3707 | I32: =RANDBETWEEN(2000,5000) -> 2319 | J32: =RANDBETWEEN(2000,5000) -> 3848
A33: DA-NANG | B33: =RANDBETWEEN(2000,5000) -> 3102 | C33: =RANDBETWEEN(2000,5000) -> 2030 | D33: =RANDBETWEEN(2000,5000) -> 4880 | E33: =RANDBETWEEN(2000,5000) -> 3125 | F33: =RANDBETWEEN(2000,5000) -> 3713 | G33: =RANDBETWEEN(2000,5000) -> 4236 | H33: =RANDBETWEEN(2000,5000) -> 4265 | I33: =RANDBETWEEN(2000,5000) -> 4688 | J33: =RANDBETWEEN(2000,5000) -> 4781
A34: ΡΗΝΟΜ ΡΕΝ | B34: =RANDBETWEEN(2000,5000) -> 3549 | C34: =RANDBETWEEN(2000,5000) -> 4062 | D34: =RANDBETWEEN(2000,5000) -> 2518 | E34: =RANDBETWEEN(2000,5000) -> 4763 | F34: =RANDBETWEEN(2000,5000) -> 4093 | G34: =RANDBETWEEN(2000,5000) -> 4474 | H34: =RANDBETWEEN(2000,5000) -> 4191 | I34: =RANDBETWEEN(2000,5000) -> 3554 | J34: =RANDBETWEEN(2000,5000) -> 2226
A35: SlHANOUKVlLLE | B35: =RANDBETWEEN(2000,5000) -> 3172 | C35: =RANDBETWEEN(2000,5000) -> 4369 | D35: =RANDBETWEEN(2000,5000) -> 4735 | E35: =RANDBETWEEN(2000,5000) -> 2697 | F35: =RANDBETWEEN(2000,5000) -> 2688 | G35: =RANDBETWEEN(2000,5000) -> 2812 | H35: =RANDBETWEEN(2000,5000) -> 3805 | I35: =RANDBETWEEN(2000,5000) -> 2604 | J35: =RANDBETWEEN(2000,5000) -> 3829
A36: <ANGON | B36: =RANDBETWEEN(2000,5000) -> 3005 | C36: =RANDBETWEEN(2000,5000) -> 3875 | D36: =RANDBETWEEN(2000,5000) -> 3228 | E36: =RANDBETWEEN(2000,5000) -> 4678 | F36: =RANDBETWEEN(2000,5000) -> 2772 | G36: =RANDBETWEEN(2000,5000) -> 2620 | H36: =RANDBETWEEN(2000,5000) -> 4939 | I36: =RANDBETWEEN(2000,5000) -> 3490 | J36: =RANDBETWEEN(2000,5000) -> 4639
A37: ΜΑΝΙΙΙΑ | B37: =RANDBETWEEN(2000,5000) -> 4776 | C37: =RANDBETWEEN(2000,5000) -> 3838 | D37: =RANDBETWEEN(2000,5000) -> 2330 | E37: =RANDBETWEEN(2000,5000) -> 3186 | F37: =RANDBETWEEN(2000,5000) -> 3172 | G37: =RANDBETWEEN(2000,5000) -> 2674 | H37: =RANDBETWEEN(2000,5000) -> 3872 | I37: =RANDBETWEEN(2000,5000) -> 4892 | J37: =RANDBETWEEN(2000,5000) -> 3753
A38: BlJSAN-KRPlJS | B38: =RANDBETWEEN(2000,5000) -> 2245 | C38: =RANDBETWEEN(2000,5000) -> 3299 | D38: =RANDBETWEEN(2000,5000) -> 4574 | E38: =RANDBETWEEN(2000,5000) -> 4215 | F38: =RANDBETWEEN(2000,5000) -> 4500 | G38: =RANDBETWEEN(2000,5000) -> 3098 | H38: =RANDBETWEEN(2000,5000) -> 2727 | I38: =RANDBETWEEN(2000,5000) -> 2574 | J38: =RANDBETWEEN(2000,5000) -> 2902
A39: GWANGYANG | B39: =RANDBETWEEN(2000,5000) -> 2887 | C39: =RANDBETWEEN(2000,5000) -> 4362 | D39: =RANDBETWEEN(2000,5000) -> 3353 | E39: =RANDBETWEEN(2000,5000) -> 4898 | F39: =RANDBETWEEN(2000,5000) -> 2222 | G39: =RANDBETWEEN(2000,5000) -> 4385 | H39: =RANDBETWEEN(2000,5000) -> 2292 | I39: =RANDBETWEEN(2000,5000) -> 2863 | J39: =RANDBETWEEN(2000,5000) -> 2508
A40: KAOHSllJNG | B40: =RANDBETWEEN(2000,5000) -> 2835 | C40: =RANDBETWEEN(2000,5000) -> 4831 | D40: =RANDBETWEEN(2000,5000) -> 3462 | E40: =RANDBETWEEN(2000,5000) -> 4955 | F40: =RANDBETWEEN(2000,5000) -> 3273 | G40: =RANDBETWEEN(2000,5000) -> 2344 | H40: =RANDBETWEEN(2000,5000) -> 2791 | I40: =RANDBETWEEN(2000,5000) -> 3054 | J40: =RANDBETWEEN(2000,5000) -> 4964
... A49: ΗΑΚΑΤΑ | B49: =RANDBETWEEN(2000,5000) -> 4483 | C49: =RANDBETWEEN(2000,5000) -> 4598 | D49: =RANDBETWEEN(2000,5000) -> 2643 | E49: =RANDBETWEEN(2000,5000) -> 2036 | F49: =RANDBETWEEN(2000,5000) -> 3613 | G49: =RANDBETWEEN(2000,5000) -> 2153 | H49: =RANDBETWEEN(2000,5000) -> 2826 | I49: =RANDBETWEEN(2000,5000) -> 2004 | J49: =RANDBETWEEN(2000,5000) -> 2758

Sheet B
A1: POD | B1: GENOVA | E1: LA SPEZIA | H1: VENEZIA | K1: TRIESTE | N1: RAVENNA | Q1: ANCONA | T1: BARI
A2: POL | B2: 20'G | C2: 40'G | D2: 40HG | E2: 20'S | F2: 40'S | G2: 40HS | H2: 20'V | I2: 40'V | J2: 40HV | K2: 20'T | L2: 40'T | M2: 40HT | N2: 20'R | O2: 40'R | P2: 40HR | Q2: 20'A | R2: 40'A | S2: 40HA | T2: 20'B | U2: 40'B | V2: 40HB
A3: YANTIAN | B3: =RANDBETWEEN(2000,6000) -> 5293 | C3: =RANDBETWEEN(2000,6000) -> 3264 | D3: =RANDBETWEEN(2000,6000) -> 2491 | E3: =RANDBETWEEN(2000,6000) -> 5273 | F3: =RANDBETWEEN(2000,6000) -> 4069 | G3: =RANDBETWEEN(2000,6000) -> 2419 | H3: =RANDBETWEEN(2000,6000) -> 4705 | I3: =RANDBETWEEN(2000,6000) -> 2481 | ... V3: =RANDBETWEEN(2000,6000) -> 3920 | X3: SHANGHAI
A4: HONG KONG | B4: =RANDBETWEEN(2000,6000) -> 3184 | C4: =RANDBETWEEN(2000,6000) -> 4951 | D4: =RANDBETWEEN(2000,6000) -> 3959 | E4: =RANDBETWEEN(2000,6000) -> 3487 | F4: =RANDBETWEEN(2000,6000) -> 3009 | G4: =RANDBETWEEN(2000,6000) -> 2177 | H4: =RANDBETWEEN(2000,6000) -> 3815 | I4: =RANDBETWEEN(2000,6000) -> 4024 | ... V4: =RANDBETWEEN(2000,6000) -> 5573 | X4: 40HA
A5: SHANGHAI | B5: =RANDBETWEEN(2000,6000) -> 3552 | C5: =RANDBETWEEN(2000,6000) -> 5750 | D5: =RANDBETWEEN(2000,6000) -> 5280 | E5: =RANDBETWEEN(2000,6000) -> 4507 | F5: =RANDBETWEEN(2000,6000) -> 2865 | G5: =RANDBETWEEN(2000,6000) -> 3143 | H5: =RANDBETWEEN(2000,6000) -> 3806 | I5: =RANDBETWEEN(2000,6000) -> 5102 | ... V5: =RANDBETWEEN(2000,6000) -> 5582
A6: NINGBO | B6: =RANDBETWEEN(2000,6000) -> 5457 | C6: =RANDBETWEEN(2000,6000) -> 4739 | D6: =RANDBETWEEN(2000,6000) -> 2364 | E6: =RANDBETWEEN(2000,6000) -> 2447 | F6: =RANDBETWEEN(2000,6000) -> 4440 | G6: =RANDBETWEEN(2000,6000) -> 3993 | H6: =RANDBETWEEN(2000,6000) -> 3621 | I6: =RANDBETWEEN(2000,6000) -> 3191 | ... V6: =RANDBETWEEN(2000,6000) -> 5340
A7: SHEKOU | B7: =RANDBETWEEN(2000,6000) -> 4174 | C7: =RANDBETWEEN(2000,6000) -> 4758 | D7: =RANDBETWEEN(2000,6000) -> 2037 | E7: =RANDBETWEEN(2000,6000) -> 3172 | F7: =RANDBETWEEN(2000,6000) -> 4627 | G7: =RANDBETWEEN(2000,6000) -> 3678 | H7: =RANDBETWEEN(2000,6000) -> 5748 | I7: =RANDBETWEEN(2000,6000) -> 3425 | ... M7: =RANDBETWEEN(2000,6000) -> 2851
A8: QINGDAO | B8: =RANDBETWEEN(2000,6000) -> 4778 | C8: =RANDBETWEEN(2000,6000) -> 3562 | D8: =RANDBETWEEN(2000,6000) -> 3605 | E8: =RANDBETWEEN(2000,6000) -> 2846 | F8: =RANDBETWEEN(2000,6000) -> 2399 | G8: =RANDBETWEEN(2000,6000) -> 3248 | H8: =RANDBETWEEN(2000,6000) -> 5715 | I8: =RANDBETWEEN(2000,6000) -> 5537 | ... V8: =RANDBETWEEN(2000,6000) -> 4489 | Z8: + Usd 104/20’ – Usd 208/40’
A9: DALIAN | B9: =RANDBETWEEN(2000,6000) -> 5534 | C9: =RANDBETWEEN(2000,6000) -> 5854 | D9: =RANDBETWEEN(2000,6000) -> 5955 | E9: =RANDBETWEEN(2000,6000) -> 4699 | F9: =RANDBETWEEN(2000,6000) -> 2969 | G9: =RANDBETWEEN(2000,6000) -> 3129 | H9: =RANDBETWEEN(2000,6000) -> 4731 | I9: =RANDBETWEEN(2000,6000) -> 4002 | ... V9: =RANDBETWEEN(2000,6000) -> 2002 | Z9: + nostro profit usd 50/20’ box – usd 100/40’box-40hc
A10: XINGANG | B10: =RANDBETWEEN(2000,6000) -> 4739 | C10: =RANDBETWEEN(2000,6000) -> 5544 | D10: =RANDBETWEEN(2000,6000) -> 2252 | E10: =RANDBETWEEN(2000,6000) -> 2836 | F10: =RANDBETWEEN(2000,6000) -> 3499 | G10: =RANDBETWEEN(2000,6000) -> 3731 | H10: =RANDBETWEEN(2000,6000) -> 4819 | I10: =RANDBETWEEN(2000,6000) -> 2827 | ... V10: =RANDBETWEEN(2000,6000) -> 2482 | Z10: total for 20' box | AC10: 154
A11: XIAMEN | B11: =RANDBETWEEN(2000,6000) -> 5301 | C11: =RANDBETWEEN(2000,6000) -> 3743 | D11: =RANDBETWEEN(2000,6000) -> 4446 | E11: =RANDBETWEEN(2000,6000) -> 4040 | F11: =RANDBETWEEN(2000,6000) -> 3529 | G11: =RANDBETWEEN(2000,6000) -> 2121 | H11: =RANDBETWEEN(2000,6000) -> 3213 | I11: =RANDBETWEEN(2000,6000) -> 4133 | ... V11: =RANDBETWEEN(2000,6000) -> 2901 | Z11: total for 40' box | AC11: 308
A12: NANSHA | B12: =RANDBETWEEN(2000,6000) -> 3120 | C12: =RANDBETWEEN(2000,6000) -> 2055 | D12: =RANDBETWEEN(2000,6000) -> 2775 | E12: =RANDBETWEEN(2000,6000) -> 2681 | F12: =RANDBETWEEN(2000,6000) -> 3936 | G12: =RANDBETWEEN(2000,6000) -> 3881 | H12: =RANDBETWEEN(2000,6000) -> 3842 | I12: =RANDBETWEEN(2000,6000) -> 5687 | ... V12: =RANDBETWEEN(2000,6000) -> 2265 | Z12: total for 40' box-hc | AC12: 308
A13: FUZHOU | B13: =RANDBETWEEN(2000,6000) -> 3048 | C13: =RANDBETWEEN(2000,6000) -> 3042 | D13: =RANDBETWEEN(2000,6000) -> 4571 | E13: =RANDBETWEEN(2000,6000) -> 3824 | F13: =RANDBETWEEN(2000,6000) -> 5785 | G13: =RANDBETWEEN(2000,6000) -> 3537 | H13: =RANDBETWEEN(2000,6000) -> 4430 | I13: =RANDBETWEEN(2000,6000) -> 3713 | ... V13: =RANDBETWEEN(2000,6000) -> 4894
A14: HUANGPU | B14: =RANDBETWEEN(2000,6000) -> 4320 | C14: =RANDBETWEEN(2000,6000) -> 4528 | D14: =RANDBETWEEN(2000,6000) -> 5456 | E14: =RANDBETWEEN(2000,6000) -> 3243 | F14: =RANDBETWEEN(2000,6000) -> 3526 | G14: =RANDBETWEEN(2000,6000) -> 4124 | H14: =RANDBETWEEN(2000,6000) -> 4523 | I14: =RANDBETWEEN(2000,6000) -> 2031 | ... V14: =RANDBETWEEN(2000,6000) -> 3478 | AC14: =VLOOKUP(X3,A2:V80,MATCH(X4,A2:V2,0),FALSE) -> 4564
A15: JIAO XIN | B15: =RANDBETWEEN(2000,6000) -> 2798 | C15: =RANDBETWEEN(2000,6000) -> 3678 | D15: =RANDBETWEEN(2000,6000) -> 2133 | E15: =RANDBETWEEN(2000,6000) -> 5608 | F15: =RANDBETWEEN(2000,6000) -> 3790 | G15: =RANDBETWEEN(2000,6000) -> 5407 | H15: =RANDBETWEEN(2000,6000) -> 3271 | I15: =RANDBETWEEN(2000,6000) -> 4722 | ... V15: =RANDBETWEEN(2000,6000) -> 2485
A16: JIUJIANG, GAOMING | B16: =RANDBETWEEN(2000,6000) -> 4401 | C16: =RANDBETWEEN(2000,6000) -> 3024 | D16: =RANDBETWEEN(2000,6000) -> 5992 | E16: =RANDBETWEEN(2000,6000) -> 2900 | F16: =RANDBETWEEN(2000,6000) -> 2052 | G16: =RANDBETWEEN(2000,6000) -> 3863 | H16: =RANDBETWEEN(2000,6000) -> 4046 | I16: =RANDBETWEEN(2000,6000) -> 2936 | ... V16: =RANDBETWEEN(2000,6000) -> 2842
A17: NANHAI, SANSHUI | B17: =RANDBETWEEN(2000,6000) -> 5360 | C17: =RANDBETWEEN(2000,6000) -> 5447 | D17: =RANDBETWEEN(2000,6000) -> 2247 | E17: =RANDBETWEEN(2000,6000) -> 5708 | F17: =RANDBETWEEN(2000,6000) -> 4822 | G17: =RANDBETWEEN(2000,6000) -> 2701 | H17: =RANDBETWEEN(2000,6000) -> 5459 | I17: =RANDBETWEEN(2000,6000) -> 3224 | ... V17: =RANDBETWEEN(2000,6000) -> 4215
A18: JIANGMEN | B18: =RANDBETWEEN(2000,6000) -> 4428 | C18: =RANDBETWEEN(2000,6000) -> 5519 | D18: =RANDBETWEEN(2000,6000) -> 5211 | E18: =RANDBETWEEN(2000,6000) -> 2372 | F18: =RANDBETWEEN(2000,6000) -> 2497 | G18: =RANDBETWEEN(2000,6000) -> 2588 | H18: =RANDBETWEEN(2000,6000) -> 4012 | I18: =RANDBETWEEN(2000,6000) -> 3852 | ... V18: =RANDBETWEEN(2000,6000) -> 2083
A19: SHANTOU | B19: =RANDBETWEEN(2000,6000) -> 5690 | C19: =RANDBETWEEN(2000,6000) -> 3030 | D19: =RANDBETWEEN(2000,6000) -> 2994 | E19: =RANDBETWEEN(2000,6000) -> 4394 | F19: =RANDBETWEEN(2000,6000) -> 4933 | G19: =RANDBETWEEN(2000,6000) -> 5397 | H19: =RANDBETWEEN(2000,6000) -> 2226 | I19: =RANDBETWEEN(2000,6000) -> 3003 | ... V19: =RANDBETWEEN(2000,6000) -> 3896
A20: TAIZHOU | B20: =RANDBETWEEN(2000,6000) -> 2667 | C20: =RANDBETWEEN(2000,6000) -> 5142 | D20: =RANDBETWEEN(2000,6000) -> 3665 | E20: =RANDBETWEEN(2000,6000) -> 5575 | F20: =RANDBETWEEN(2000,6000) -> 2189 | G20: =RANDBETWEEN(2000,6000) -> 5984 | H20: =RANDBETWEEN(2000,6000) -> 2776 | I20: =RANDBETWEEN(2000,6000) -> 2024 | ... V20: =RANDBETWEEN(2000,6000) -> 5661
A21: WUHAN | B21: =RANDBETWEEN(2000,6000) -> 3107 | C21: =RANDBETWEEN(2000,6000) -> 2019 | D21: =RANDBETWEEN(2000,6000) -> 4158 | E21: =RANDBETWEEN(2000,6000) -> 3484 | F21: =RANDBETWEEN(2000,6000) -> 4804 | G21: =RANDBETWEEN(2000,6000) -> 4486 | H21: =RANDBETWEEN(2000,6000) -> 2220 | I21: =RANDBETWEEN(2000,6000) -> 4844 | ... N21: =RANDBETWEEN(2000,6000) -> 4208 | O21: 333 | P21: =RANDBETWEEN(2000,6000) -> 5551 | Q21: =RANDBETWEEN(2000,6000) -> 4869 | R21: =RANDBETWEEN(2000,6000) -> 5215 | S21: =RANDBETWEEN(2000,6000) -> 5999 | T21: =RANDBETWEEN(2000,6000) -> 2774 | U21: =RANDBETWEEN(2000,6000) -> 2616 | V21: =RANDBETWEEN(2000,6000) -> 3297
A22: XIAO LAN | B22: =RANDBETWEEN(2000,6000) -> 3323 | C22: =RANDBETWEEN(2000,6000) -> 5888 | D22: =RANDBETWEEN(2000,6000) -> 4800 | E22: =RANDBETWEEN(2000,6000) -> 2903 | F22: =RANDBETWEEN(2000,6000) -> 2253 | G22: =RANDBETWEEN(2000,6000) -> 4235 | H22: =RANDBETWEEN(2000,6000) -> 3016 | I22: =RANDBETWEEN(2000,6000) -> 4237 | ... V22: =RANDBETWEEN(2000,6000) -> 5910
A23: ZHAN JIANG | B23: =RANDBETWEEN(2000,6000) -> 5405 | C23: =RANDBETWEEN(2000,6000) -> 2139 | D23: =RANDBETWEEN(2000,6000) -> 3891 | E23: =RANDBETWEEN(2000,6000) -> 4106 | F23: =RANDBETWEEN(2000,6000) -> 4249 | G23: =RANDBETWEEN(2000,6000) -> 2233 | H23: =RANDBETWEEN(2000,6000) -> 5530 | I23: =RANDBETWEEN(2000,6000) -> 3551 | ... V23: =RANDBETWEEN(2000,6000) -> 3378
A24: ZHAO QING | B24: =RANDBETWEEN(2000,6000) -> 2917 | C24: =RANDBETWEEN(2000,6000) -> 3601 | D24: =RANDBETWEEN(2000,6000) -> 4655 | E24: =RANDBETWEEN(2000,6000) -> 5215 | F24: =RANDBETWEEN(2000,6000) -> 2297 | G24: =RANDBETWEEN(2000,6000) -> 4707 | H24: =RANDBETWEEN(2000,6000) -> 4155 | I24: =RANDBETWEEN(2000,6000) -> 3379 | ... V24: =RANDBETWEEN(2000,6000) -> 3094
A25: LIANYUNGANG | B25: =RANDBETWEEN(2000,6000) -> 2362 | C25: =RANDBETWEEN(2000,6000) -> 2104 | D25: =RANDBETWEEN(2000,6000) -> 5393 | E25: =RANDBETWEEN(2000,6000) -> 2584 | F25: =RANDBETWEEN(2000,6000) -> 5149 | G25: =RANDBETWEEN(2000,6000) -> 4647 | H25: =RANDBETWEEN(2000,6000) -> 4929 | I25: =RANDBETWEEN(2000,6000) -> 3771 | ... V25: =RANDBETWEEN(2000,6000) -> 4294
A26: WUZHOU | B26: =RANDBETWEEN(2000,6000) -> 5274 | C26: =RANDBETWEEN(2000,6000) -> 4866 | D26: =RANDBETWEEN(2000,6000) -> 4198 | E26: =RANDBETWEEN(2000,6000) -> 2717 | F26: =RANDBETWEEN(2000,6000) -> 4485 | G26: =RANDBETWEEN(2000,6000) -> 4590 | H26: =RANDBETWEEN(2000,6000) -> 3369 | I26: =RANDBETWEEN(2000,6000) -> 2957 | ... V26: =RANDBETWEEN(2000,6000) -> 3166
A27: HAIKOU | B27: =RANDBETWEEN(2000,6000) -> 2104 | C27: =RANDBETWEEN(2000,6000) -> 4162 | D27: =RANDBETWEEN(2000,6000) -> 2962 | E27: =RANDBETWEEN(2000,6000) -> 5384 | F27: =RANDBETWEEN(2000,6000) -> 2884 | G27: =RANDBETWEEN(2000,6000) -> 2657 | H27: =RANDBETWEEN(2000,6000) -> 2430 | I27: =RANDBETWEEN(2000,6000) -> 3266 | ... V27: =RANDBETWEEN(2000,6000) -> 4455
A28: CHONG QING | B28: =RANDBETWEEN(2000,6000) -> 5992 | C28: =RANDBETWEEN(2000,6000) -> 4041 | D28: =RANDBETWEEN(2000,6000) -> 4655 | E28: =RANDBETWEEN(2000,6000) -> 4333 | F28: =RANDBETWEEN(2000,6000) -> 5637 | G28: =RANDBETWEEN(2000,6000) -> 3325 | H28: =RANDBETWEEN(2000,6000) -> 5547 | I28: =RANDBETWEEN(2000,6000) -> 2938 | ... V28: =RANDBETWEEN(2000,6000) -> 5978
A29: ZHONGSHAN | B29: =RANDBETWEEN(2000,6000) -> 4099 | C29: =RANDBETWEEN(2000,6000) -> 5121 | D29: =RANDBETWEEN(2000,6000) -> 3770 | E29: =RANDBETWEEN(2000,6000) -> 4856 | F29: =RANDBETWEEN(2000,6000) -> 2835 | G29: =RANDBETWEEN(2000,6000) -> 3766 | H29: =RANDBETWEEN(2000,6000) -> 5238 | I29: =RANDBETWEEN(2000,6000) -> 2005 | ... V29: =RANDBETWEEN(2000,6000) -> 5696
A30: RONGQI | B30: =RANDBETWEEN(2000,6000) -> 5510 | C30: =RANDBETWEEN(2000,6000) -> 3932 | D30: =RANDBETWEEN(2000,6000) -> 5589 | E30: =RANDBETWEEN(2000,6000) -> 4219 | F30: =RANDBETWEEN(2000,6000) -> 5364 | G30: =RANDBETWEEN(2000,6000) -> 2069 | H30: =RANDBETWEEN(2000,6000) -> 4330 | I30: =RANDBETWEEN(2000,6000) -> 2657 | ... V30: =RANDBETWEEN(2000,6000) -> 5040
A31: BEIJIAO | B31: =RANDBETWEEN(2000,6000) -> 4843 | C31: =RANDBETWEEN(2000,6000) -> 4967 | D31: =RANDBETWEEN(2000,6000) -> 2154 | E31: =RANDBETWEEN(2000,6000) -> 4549 | F31: =RANDBETWEEN(2000,6000) -> 6000 | G31: =RANDBETWEEN(2000,6000) -> 3691 | H31: =RANDBETWEEN(2000,6000) -> 5596 | I31: =RANDBETWEEN(2000,6000) -> 2136 | ... V31: =RANDBETWEEN(2000,6000) -> 2120
A32: ZHUHAI | B32: =RANDBETWEEN(2000,6000) -> 3969 | C32: =RANDBETWEEN(2000,6000) -> 2906 | D32: =RANDBETWEEN(2000,6000) -> 4063 | E32: =RANDBETWEEN(2000,6000) -> 5838 | F32: =RANDBETWEEN(2000,6000) -> 4036 | G32: =RANDBETWEEN(2000,6000) -> 4843 | H32: =RANDBETWEEN(2000,6000) -> 3711 | I32: =RANDBETWEEN(2000,6000) -> 2726 | ... V32: =RANDBETWEEN(2000,6000) -> 5427
A33: LELIU | B33: =RANDBETWEEN(2000,6000) -> 4855 | C33: =RANDBETWEEN(2000,6000) -> 2262 | D33: =RANDBETWEEN(2000,6000) -> 2687 | E33: =RANDBETWEEN(2000,6000) -> 3360 | F33: =RANDBETWEEN(2000,6000) -> 4935 | G33: =RANDBETWEEN(2000,6000) -> 2604 | H33: =RANDBETWEEN(2000,6000) -> 5312 | I33: =RANDBETWEEN(2000,6000) -> 2855 | ... V33: =RANDBETWEEN(2000,6000) -> 3717
... A80: CHENNAI | B80: =RANDBETWEEN(2000,6000) -> 5782 | C80: =RANDBETWEEN(2000,6000) -> 3925 | D80: =RANDBETWEEN(2000,6000) -> 3533 | E80: =RANDBETWEEN(2000,6000) -> 3232 | F80: =RANDBETWEEN(2000,6000) -> 2887 | G80: =RANDBETWEEN(2000,6000) -> 2209 | H80: =RANDBETWEEN(2000,6000) -> 2299 | I80: =RANDBETWEEN(2000,6000) -> 5207 | ... V80: =RANDBETWEEN(2000,6000) -> 3330

Sheet C
A1: ORIGIN | B1: GENOA / LA SPEZIA | E1: NAP/LIV/VCE/SAL/AOI
A2: Port of Loading | B2: 20' GS | C2: 40' GS | D2: 40H GS | E2: 20' NLVSA | F2: 40' NLVSA | G2: 40H NLVSA
A3: Chattogram | B3: =RANDBETWEEN(2000,5000) -> 4427 | C3: =RANDBETWEEN(2000,5000) -> 3437 | D3: =RANDBETWEEN(2000,5000) -> 2997 | E3: =RANDBETWEEN(2000,5000) -> 2568 | F3: =RANDBETWEEN(2000,5000) -> 2814 | G3: =RANDBETWEEN(2000,5000) -> 3838 | I3: 40H GS
A4: DHAKA | B4: =RANDBETWEEN(2000,5000) -> 2419 | C4: =RANDBETWEEN(2000,5000) -> 3093 | D4: =RANDBETWEEN(2000,5000) -> 2648 | E4: =RANDBETWEEN(2000,5000) -> 4568 | F4: =RANDBETWEEN(2000,5000) -> 2639 | G4: =RANDBETWEEN(2000,5000) -> 2304 | I4: BEIJIAO,SHUNDE
A5: ANQING | B5: =RANDBETWEEN(2000,5000) -> 3639 | C5: =RANDBETWEEN(2000,5000) -> 2054 | D5: =RANDBETWEEN(2000,5000) -> 3897 | E5: =RANDBETWEEN(2000,5000) -> 2942 | F5: =RANDBETWEEN(2000,5000) -> 4536 | G5: =RANDBETWEEN(2000,5000) -> 2774
A6: BEIJIAO,SHUNDE | B6: =RANDBETWEEN(2000,5000) -> 4542 | C6: =RANDBETWEEN(2000,5000) -> 4133 | D6: =RANDBETWEEN(2000,5000) -> 3388 | E6: =RANDBETWEEN(2000,5000) -> 2451 | F6: =RANDBETWEEN(2000,5000) -> 3163 | G6: =RANDBETWEEN(2000,5000) -> 3958
A7: CHONGQING | B7: =RANDBETWEEN(2000,5000) -> 3470 | C7: =RANDBETWEEN(2000,5000) -> 3384 | D7: =RANDBETWEEN(2000,5000) -> 3114 | E7: =RANDBETWEEN(2000,5000) -> 2257 | F7: =RANDBETWEEN(2000,5000) -> 4716 | G7: =RANDBETWEEN(2000,5000) -> 4439 | K7: + USD 30/20’-40’-40HC
A8: CHANGSHA | B8: =RANDBETWEEN(2000,5000) -> 3798 | C8: =RANDBETWEEN(2000,5000) -> 4732 | D8: =RANDBETWEEN(2000,5000) -> 2340 | E8: =RANDBETWEEN(2000,5000) -> 4007 | F8: =RANDBETWEEN(2000,5000) -> 4186 | G8: =RANDBETWEEN(2000,5000) -> 3473 | K8: + USD 8/20’ – USD 16/40’-40HC
A9: CHANGZHOU | B9: =RANDBETWEEN(2000,5000) -> 3136 | C9: =RANDBETWEEN(2000,5000) -> 2379 | D9: =RANDBETWEEN(2000,5000) -> 4134 | E9: =RANDBETWEEN(2000,5000) -> 4671 | F9: =RANDBETWEEN(2000,5000) -> 3477 | G9: =RANDBETWEEN(2000,5000) -> 3208 | K9: + ns profit USD 50/20’ – USD 100/40’-40HC
A10: DALIAN,LN | B10: =RANDBETWEEN(2000,5000) -> 4378 | C10: =RANDBETWEEN(2000,5000) -> 3499 | D10: =RANDBETWEEN(2000,5000) -> 2487 | E10: =RANDBETWEEN(2000,5000) -> 3492 | F10: =RANDBETWEEN(2000,5000) -> 4303 | G10: =RANDBETWEEN(2000,5000) -> 2515 | K10: total for 20' box | L10: 88
A11: FUZHOU | B11: =RANDBETWEEN(2000,5000) -> 3256 | C11: =RANDBETWEEN(2000,5000) -> 2879 | D11: =RANDBETWEEN(2000,5000) -> 2467 | E11: =RANDBETWEEN(2000,5000) -> 3415 | F11: =RANDBETWEEN(2000,5000) -> 3035 | G11: =RANDBETWEEN(2000,5000) -> 4094 | K11: total for 40' box | L11: 146
